Workbook
Name BusinessAssociates: 'Person type_Classify'!$B$1
Name ContractConsultant: 'Person type_Classify'!$D$1:$D$3
Name Employee: 'Person type_Classify'!$C$1:$C$3
Name Intern: 'Person type_Classify'!$E$1:$E$6

Sheet Template
A1: Last Name* | B1: Sánchez Vidals
A2: First Name* | B2: Luis
A3: Middle Name | B3: Felipe
A4: Title ( Mr. / Ms./ Dr)* (use Dropdown) | B4: Mr.
A5: Preferred Name* | B5: Felipe
A6: Male / Female * (use Dropdown) | B6: Male
A7: Date of Birth ( DD - MMM - YYYY)* | B7: 32964
A8: Town of Birth | B8: Acatlan
A9: Country of Birth* | B9: Puebla
A10: Marital Status ( Married / Single )* (use Dropdown) | B10: Cohabitation
A11: Nationality* | B11: Mexican
A12: Citizenship | B12: Mexican
A13: National Identification Number | B13: SAVL900401HPLNDS04
A14: Employee's IMSS Number | B14: 48129044540
A15: Employee's RFC | B15: SAVL900401238
A16: B ) ADDRESS DETAILS
A17: Present Address | B17: Insurgentes Sur 4411 exit to Cuernavaca and univ interconental tlalcoligia
A18: City | B18: Tlalpan, CDMX
A19: State | B19: CDMX
A20: Country | B20: Mexico
A21: Pin Code | B21: 14430
A22: Telephone No.( country code ) telephone no | B22: 5215574860931
A23: D ) BANK DETAILS
A24: Bank name | B24: Banco Azteca
A25: Bank account number | B25: 1.2718e+17
A26: Bank account type | B26: Debito
A27: E ) EDUCATIONAL DETAILS
A28: F ) Graduation
A29: Name of Institute | B29: Benemerita Universidad Autonoma de Puebla
A30: Start date of Course | B30: 2009
A31: End date of course | B31: 2015
A32: Full time / Part time course | B32: Full time
A33: Status ( Completed /Incomplete / Ongoing ) | B33: Completed
A34: Qualification Category | B34: Diploma
A35: Qualification | B35: Diploma
A36: H ) PRIOR WORK EXPERIENCE
A37: Name of prevous organisation ( 1 ) (mandatory only if Rel Experience is >0) *
A38: Start date ( DD - MMM - YYYY) * | B38: 41699
A39: End date ( DD - MMM - YYYY) * | B39: 43282
A40: Name of prevous organisation ( 2 )
...

Sheet Sheet1
A1: Total de años de experiencia
B2: Meses
A3: 1 | B3: =DATEDIF(Template!B38,Template!B39,"m") -> 52
A4: 2 | B4: =DATEDIF(Template!B41,Template!B42,"m") -> 20
A5: 3 | B5: =DATEDIF(Template!B44,Template!B45,"m") -> 9
A6: 4 | B6: =DATEDIF(Template!B47,Template!B48,"m") -> 34
A7: 5 | B7: =DATEDIF(Template!B50,Template!B51,"m") -> 6
A8: 6 | B8: =DATEDIF(Template!#REF!,Template!#REF!,"m") -> #REF!
A9: 7 | B9: =DATEDIF(Template!#REF!,Template!#REF!,"m") -> #REF!
A10: 8 | B10: =DATEDIF(Template!#REF!,Template!#REF!,"m") -> #REF!
A11: 9 | B11: =DATEDIF(Template!#REF!,Template!#REF!,"m") -> #REF!
A12: 10 | B12: =DATEDIF(Template!#REF!,Template!#REF!,"m") -> #REF!
A13: 11 | B13: =DATEDIF(Template!#REF!,Template!#REF!,"m") -> #REF!
A14: 12 | B14: =DATEDIF(Template!#REF!,Template!#REF!,"m") -> #REF!
A15: TOTAL: | D15: =SUM(B3,B4,B5,B6,B7,B8,B9,B10,B11,B12,B13)/12 -> #REF!

Sheet Nomina
A1: Hiring Authorization Form
A2: Salary | B2: Salary
B3: Scheme
A4: Position's Name
A5: Project Name
A6: Payroll Details | B6: Employee's IMSS number:
B7: Employee's RFC :
B8: Employee's CURP:
B9: Employee father's name:
B10: Employee mother's name:
B11: Bank Account

Sheet DATA Base Format
A1: SECTOR | B1: COUNTRY | C1: Date of Joining ( DD - MON - YYYY)* | D1: A ) PERSONAL | Q1: Y ) ADDRESS DETAILS | W1: C ) ASSIGNMENT DETAILS | AI1: D ) EDUCATIONAL DETAILS | AY1: E ) PRIOR WORK EXPERIENCE | BN1: F ) ALLOCATION DETAILS | BX1: G ) RECRUITMENT DATA | CF1: VISA details | CK1: Employee NumYer | CL1: Employee Name | CM1: Applicant ID | CN1: Offer Letter Rolled in iBegin (If Yes - Applicant ID is Mandatory)
D2: Last Name* | E2: First Name* | F2: Middle Name | G2: Title ( Mr. / Ms./ Dr)* (use Dropdown) | H2: Preferred Name* | I2: Male / Female * (use Dropdown) | J2: Date of Birth ( DD - MMM - YYYY)* | K2: Town of Birth | L2: Country of Birth* | M2: Marital Status ( Married / Single )* (use Dropdown) | N2: Nationality* | O2: Citizenship | P2: National Identification Number | Q2: Present Address | R2: City | S2: State | T2: Country | U2: Pin Code | V2: Telephone No.( country code ) telephone no | W2: Probation period ( months ) - Only for permanent employees | X2: Organisation* ( ie. Base Delivery Centre ) | Y2: Grade* | Z2: Location (Working Location) * | AA2: Department* | AB2: Designation* | AC2: Designation Code* | AD2: CC / Non CC (CC - Computer Consultancy & Non CC - Support) | AE2: Person Type* (use Dropdown) | AF2: Only For Person Type Intern Associates (use Dropdown) | AG2: Employee Category | AH2: Payroll | AI2: I ) Graduation | AJ2: Name of Institute | AK2: Start date of Course | AL2: End date of course | AM2: Full time / Part time course | AN2: Status ( Completed /Incomplete / Ongoing ) | AO2: Qualification Category | AP2: Qualification | AQ2: II ) Post Graduation | AR2: Name of Institute | AS2: Start date of Course | AT2: End date of course | AU2: Full time / Part time course | AV2: Status ( Completed /Incomplete / Ongoing ) | AW2: Qualification Category * (mandatory only for Post Gratuates) | AX2: Qualification * | AY2: Name of prevous organisation ( 1 ) (mandatory only if Rel Experience is >0) * | AZ2: Start date ( DD - MMM - YYYY) * | BA2: End date ( DD - MMM - YYYY) * | BB2: Name of prevous organisation ( 2 ) | BC2: Start date ( DD - MMM - YYYY) | BD2: End date ( DD - MMM - YYYY) | BE2: Name of prevous organisation ( 3 ) | BF2: Start date ( DD - MMM - YYYY) | BG2: End date ( DD - MMM - YYYY) | BH2: Name of prevous organisation ( n ) | BI2: Start date ( DD - MMM - YYYY) | BJ2: End date ( DD - MMM - YYYY) | BK2: Leave Details (only for UK and Ireland) | BL2: Privilege Leave ( In Days ) | BM2: Sick Leave ( In Weeks ) | BN2: Independent Operation Unit ( Child IOU Name )* | BO2: Total Years of Experience * | BP2: Relevant Years of Experience * | BQ2: RGS ID Number * | BR2: WON / Swon for allocation * | BS2: Start Date of Allocation (DD-MMM-YYYY) | BT2: Billing Rate per hour * | BU2: Account Name | BV2: Supervisor Name | BW2: Client Partner | BX2: Technical skill (Competency for which we are hiring the candidate) * | BY2: Insourcing (YES / NO) | BZ2: Sourcing Channel (Direct candidate/ YYY/ Placement Agency/ Newspaper Ad/ College hire/ JoY Fair, etc) * | CA2: Estimated cost of hiring (Placement Agency payment/ YYY reward/ other similar Sourcing channel cost) * | CB2: Interview Date 1 (Last date of Interview) * | CC2: Interview Date 2 | CD2: Interview Date 3 | CE2: Offer Date (Date when Offer letter was shared with candidate) * | CF2: Visa code | CG2: Visa Number | CH2: Issue date | CI2: Expiry date | CJ2: Country of Deputation
A3: =Template!#REF! -> #REF! | B3: =Template!$B1 -> Sánchez Vidals | C3: =Template!$B2 -> Luis | D3: =Template!$B4 -> Mr. | E3: =Template!$B5 -> Felipe | F3: =Template!$B6 -> Male | G3: =Template!$B7 -> 32964 | H3: =Template!$B8 -> Acatlan | I3: =Template!$B9 -> Puebla | J3: =Template!$B10 -> Cohabitation | K3: =Template!$B11 -> Mexican | L3: =Template!$B12 -> Mexican | M3: =Template!$B13 -> SAVL900401HPLNDS04 | N3: =Template!$B16 -> 0 | O3: =Template!$B17 -> Insurgentes Sur 4411 exit to Cuernavaca and univ interconental tlalcoligia | P3: =Template!$B18 -> Tlalpan, CDMX | Q3: =Template!$B20 -> Mexico | R3: =Template!$B21 -> 14430 | S3: =Template!$B22 -> 5215574860931 | T3: =Template!#REF! -> #REF! | U3: =Template!#REF! -> #REF! | V3: =Template!#REF! -> #REF! | W3: =Template!#REF! -> #REF! | X3: =Template!#REF! -> #REF! | Y3: =Template!#REF! -> #REF! | Z3: =Template!#REF! -> #REF! | AA3: =Template!#REF! -> #REF! | ... AE3: =Template!#REF! -> #REF! | AF3: =Template!$B28 -> 0 | AG3: =Template!$B27 -> 0 | AH3: =Template!$B29 -> Benemerita Universidad Autonoma de Puebla | AI3: =Template!$B31 -> 2015 | AJ3: =Template!$B32 -> Full time | AK3: =Template!$B33 -> Completed | AL3: =Template!$B34 -> Diploma | AM3: =Template!$B35 -> Diploma | AN3: =Template!#REF! -> #REF! | AO3: =Template!#REF! -> #REF! | AP3: =Template!#REF! -> #REF! | AQ3: =Template!#REF! -> #REF! | AR3: =Template!#REF! -> #REF! | AS3: =Template!#REF! -> #REF! | AT3: =Template!#REF! -> #REF! | AU3: =Template!#REF! -> #REF! | AV3: =Template!$B36 -> 0 | AW3: =Template!$B37 -> 0 | AX3: =Template!$B38 -> 41699 | AY3: =Template!$B40 -> 0 | AZ3: =Template!$B41 -> 41000 | BA3: =Template!$B42 -> 41638 | BB3: =Template!$B43 -> 0 | BC3: =Template!$B44 -> 39753 | BD3: =Template!$B45 -> 40055 | BE3: =Template!$B46 -> GRUPO SALINAS | BF3: =Template!$B47 -> 42391 | BG3: =Template!$B48 -> 43431 | BH3: =Template!$B52 -> 0 | BI3: =Template!$B53 -> 0 | BJ3: =Template!$B54 -> 0 | BK3: =Template!#REF! -> #REF! | BL3: =Template!#REF! -> #REF! | BM3: =Template!#REF! -> #REF! | BN3: =Template!#REF! -> #REF! | BO3: =Template!#REF! -> #REF! | BP3: =Template!#REF! -> #REF! | BQ3: =Template!#REF! -> #REF! | BR3: =Template!#REF! -> #REF! | ... CN3: =Template!#REF! -> #REF!
A4: =Template!#REF! -> #REF! | B4: =Template!#REF! -> #REF! | C4: =Template!#REF! -> #REF! | D4: =Template!#REF! -> #REF! | E4: =Template!#REF! -> #REF! | F4: =Template!#REF! -> #REF! | G4: =Template!#REF! -> #REF! | H4: =Template!#REF! -> #REF! | ... CN4: =Template!#REF! -> #REF!
A5: =Template!#REF! -> #REF! | B5: =Template!#REF! -> #REF! | C5: =Template!#REF! -> #REF! | D5: =Template!#REF! -> #REF! | E5: =Template!#REF! -> #REF! | F5: =Template!#REF! -> #REF! | G5: =Template!#REF! -> #REF! | H5: =Template!#REF! -> #REF! | ... CN5: =Template!#REF! -> #REF!
A6: =Template!#REF! -> #REF! | B6: =Template!#REF! -> #REF! | C6: =Template!#REF! -> #REF! | D6: =Template!#REF! -> #REF! | E6: =Template!#REF! -> #REF! | F6: =Template!#REF! -> #REF! | G6: =Template!#REF! -> #REF! | H6: =Template!#REF! -> #REF! | ... CN6: =Template!#REF! -> #REF!
A7: =Template!#REF! -> #REF! | B7: =Template!#REF! -> #REF! | C7: =Template!#REF! -> #REF! | D7: =Template!#REF! -> #REF! | E7: =Template!#REF! -> #REF! | F7: =Template!#REF! -> #REF! | G7: =Template!#REF! -> #REF! | H7: =Template!#REF! -> #REF! | ... CN7: =Template!#REF! -> #REF!
A8: =Template!#REF! -> #REF! | B8: =Template!#REF! -> #REF! | C8: =Template!#REF! -> #REF! | D8: =Template!#REF! -> #REF! | E8: =Template!#REF! -> #REF! | F8: =Template!#REF! -> #REF! | G8: =Template!#REF! -> #REF! | H8: =Template!#REF! -> #REF! | ... AX8: =Template!#REF! -> #REF! | AY8: =Sheet1!$A1 -> Total de años de experiencia | AZ8: =Template!#REF! -> #REF! | BA8: =Template!#REF! -> #REF! | BB8: =Template!#REF! -> #REF! | BC8: =Template!#REF! -> #REF! | BD8: =Template!#REF! -> #REF! | BE8: =Template!#REF! -> #REF! | BF8: =Template!#REF! -> #REF! | BG8: =Template!#REF! -> #REF! | ... CN8: =Template!#REF! -> #REF!
A9: =Template!#REF! -> #REF! | B9: =Template!#REF! -> #REF! | C9: =Template!#REF! -> #REF! | D9: =Template!#REF! -> #REF! | E9: =Template!#REF! -> #REF! | F9: =Template!#REF! -> #REF! | G9: =Template!#REF! -> #REF! | H9: =Template!#REF! -> #REF! | ... CN9: =Template!#REF! -> #REF!
A10: =Template!#REF! -> #REF! | B10: =Template!#REF! -> #REF! | C10: =Template!#REF! -> #REF! | D10: =Template!#REF! -> #REF! | E10: =Template!#REF! -> #REF! | F10: =Template!#REF! -> #REF! | G10: =Template!#REF! -> #REF! | H10: =Template!#REF! -> #REF! | ... CN10: =Template!#REF! -> #REF!
A11: =Template!#REF! -> #REF! | B11: =Template!#REF! -> #REF! | C11: =Template!#REF! -> #REF! | D11: =Template!#REF! -> #REF! | E11: =Template!#REF! -> #REF! | F11: =Template!#REF! -> #REF! | G11: =Template!#REF! -> #REF! | H11: =Template!#REF! -> #REF! | ... CN11: =Template!#REF! -> #REF!
A12: =Template!#REF! -> #REF! | B12: =Template!#REF! -> #REF! | C12: =Template!#REF! -> #REF! | D12: =Template!$C1 -> 0 | E12: =Template!$C2 -> 0 | F12: =Template!$C3 -> 0 | G12: =Template!$C4 -> 0 | H12: =Template!$C5 -> 0 | I12: =Template!$C6 -> 0 | J12: =Template!$C7 -> 0 | K12: =Template!$C8 -> 0 | L12: =Template!$C9 -> 0 | M12: =Template!$C10 -> 0 | N12: =Template!$C11 -> 0 | O12: =Template!$C12 -> 0 | P12: =Template!$C13 -> 0 | Q12: =Template!$C17 -> 0 | R12: =Template!$C18 -> 0 | S12: =Template!$C19 -> 0 | T12: =Template!$C20 -> 0 | U12: =Template!$C21 -> 0 | V12: =Template!$C22 -> 0 | W12: =Template!#REF! -> #REF! | X12: =Template!#REF! -> #REF! | Y12: =Template!#REF! -> #REF! | Z12: =Template!#REF! -> #REF! | AA12: =Template!#REF! -> #REF! | AB12: =Template!#REF! -> #REF! | AC12: =Template!#REF! -> #REF! | AD12: =Template!#REF! -> #REF! | ... AH12: =Template!#REF! -> #REF! | AI12: =Template!$C28 -> 0 | AJ12: =Template!$C29 -> 0 | AK12: =Template!$C30 -> 0 | AL12: =Template!$C31 -> 0 | AM12: =Template!$C32 -> 0 | AN12: =Template!$C33 -> 0 | AO12: =Template!$C34 -> 0 | AP12: =Template!$C35 -> 0 | AQ12: =Template!#REF! -> #REF! | AR12: =Template!#REF! -> #REF! | AS12: =Template!#REF! -> #REF! | AT12: =Template!#REF! -> #REF! | AU12: =Template!#REF! -> #REF! | AV12: =Template!#REF! -> #REF! | AW12: =Template!#REF! -> #REF! | AX12: =Template!#REF! -> #REF! | AY12: =Template!$C37 -> 0 | AZ12: =Template!$C38 -> 0 | BA12: =Template!$C39 -> 0 | BB12: =Template!$C40 -> 0 | BC12: =Template!$C41 -> 0 | BD12: =Template!$C42 -> 0 | BE12: =Template!$C43 -> 0 | BF12: =Template!$C44 -> 0 | BG12: =Template!$C45 -> 0 | BH12: =Template!$C46 -> 0 | BI12: =Template!$C47 -> 0 | BJ12: =Template!$C48 -> 0 | BK12: =Template!$C52 -> 0 | BL12: =Template!$C53 -> 0 | BM12: =Template!$C54 -> 0 | BN12: =Template!#REF! -> #REF! | BO12: =Template!#REF! -> #REF! | BP12: =Template!#REF! -> #REF! | BQ12: =Template!#REF! -> #REF! | BR12: =Template!#REF! -> #REF! | BS12: =Template!#REF! -> #REF! | BT12: =Template!#REF! -> #REF! | BU12: =Template!#REF! -> #REF! | ... CN12: =Template!#REF! -> #REF!
A13: =Template!#REF! -> #REF! | B13: =Template!#REF! -> #REF! | C13: =Template!#REF! -> #REF! | D13: =Template!$D1 -> 0 | E13: =Template!$D2 -> 0 | F13: =Template!$D3 -> 0 | G13: =Template!$D4 -> 0 | H13: =Template!$D5 -> 0 | I13: =Template!$D6 -> 0 | J13: =Template!$D7 -> 0 | K13: =Template!$D8 -> 0 | L13: =Template!$D9 -> 0 | M13: =Template!$D10 -> 0 | N13: =Template!$D11 -> 0 | O13: =Template!$D12 -> 0 | P13: =Template!$D13 -> 0 | Q13: =Template!$D17 -> 0 | R13: =Template!$D18 -> 0 | S13: =Template!$D19 -> 0 | T13: =Template!$D20 -> 0 | U13: =Template!$D21 -> 0 | V13: =Template!$D22 -> 0 | W13: =Template!#REF! -> #REF! | X13: =Template!#REF! -> #REF! | Y13: =Template!#REF! -> #REF! | Z13: =Template!#REF! -> #REF! | AA13: =Template!#REF! -> #REF! | AB13: =Template!#REF! -> #REF! | AC13: =Template!#REF! -> #REF! | AD13: =Template!#REF! -> #REF! | ... AH13: =Template!#REF! -> #REF! | AI13: =Template!$D28 -> 0 | AJ13: =Template!$D29 -> 0 | AK13: =Template!$D30 -> 0 | AL13: =Template!$D31 -> 0 | AM13: =Template!$D32 -> 0 | AN13: =Template!$D33 -> 0 | AO13: =Template!$D34 -> 0 | AP13: =Template!$D35 -> 0 | AQ13: =Template!#REF! -> #REF! | AR13: =Template!#REF! -> #REF! | AS13: =Template!#REF! -> #REF! | AT13: =Template!#REF! -> #REF! | AU13: =Template!#REF! -> #REF! | AV13: =Template!#REF! -> #REF! | AW13: =Template!#REF! -> #REF! | AX13: =Template!#REF! -> #REF! | AY13: =Template!$D37 -> 0 | AZ13: =Template!$D38 -> 0 | BA13: =Template!$D39 -> 0 | BB13: =Template!$D40 -> 0 | BC13: =Template!$D41 -> 0 | BD13: =Template!$D42 -> 0 | BE13: =Template!$D43 -> 0 | BF13: =Template!$D44 -> 0 | BG13: =Template!$D45 -> 0 | BH13: =Template!$D46 -> 0 | BI13: =Template!$D47 -> 0 | BJ13: =Template!$D48 -> 0 | BK13: =Template!$D52 -> 0 | BL13: =Template!$D53 -> 0 | BM13: =Template!$D54 -> 0 | BN13: =Template!#REF! -> #REF! | BO13: =Template!#REF! -> #REF! | BP13: =Template!#REF! -> #REF! | BQ13: =Template!#REF! -> #REF! | BR13: =Template!#REF! -> #REF! | BS13: =Template!#REF! -> #REF! | BT13: =Template!#REF! -> #REF! | BU13: =Template!#REF! -> #REF! | ... CN13: =Template!#REF! -> #REF!
A14: =Template!#REF! -> #REF! | B14: =Template!#REF! -> #REF! | C14: =Template!#REF! -> #REF! | D14: =Template!$E1 -> 0 | E14: =Template!$E2 -> 0 | F14: =Template!$E3 -> 0 | G14: =Template!$E4 -> 0 | H14: =Template!$E5 -> 0 | I14: =Template!$E6 -> 0 | J14: =Template!$E7 -> 0 | K14: =Template!$E8 -> 0 | L14: =Template!$E9 -> 0 | M14: =Template!$E10 -> 0 | N14: =Template!$E11 -> 0 | O14: =Template!$E12 -> 0 | P14: =Template!$E13 -> 0 | Q14: =Template!$E17 -> 0 | R14: =Template!$E18 -> 0 | S14: =Template!$E19 -> 0 | T14: =Template!$E20 -> 0 | U14: =Template!$E21 -> 0 | V14: =Template!$E22 -> 0 | W14: =Template!#REF! -> #REF! | X14: =Template!#REF! -> #REF! | Y14: =Template!#REF! -> #REF! | Z14: =Template!#REF! -> #REF! | AA14: =Template!#REF! -> #REF! | AB14: =Template!#REF! -> #REF! | AC14: =Template!#REF! -> #REF! | AD14: =Template!#REF! -> #REF! | ... AH14: =Template!#REF! -> #REF! | AI14: =Template!$E28 -> 0 | AJ14: =Template!$E29 -> 0 | AK14: =Template!$E30 -> 0 | AL14: =Template!$E31 -> 0 | AM14: =Template!$E32 -> 0 | AN14: =Template!$E33 -> 0 | AO14: =Template!$E34 -> 0 | AP14: =Template!$E35 -> 0 | AQ14: =Template!#REF! -> #REF! | AR14: =Template!#REF! -> #REF! | AS14: =Template!#REF! -> #REF! | AT14: =Template!#REF! -> #REF! | AU14: =Template!#REF! -> #REF! | AV14: =Template!#REF! -> #REF! | AW14: =Template!#REF! -> #REF! | AX14: =Template!#REF! -> #REF! | AY14: =Template!$E37 -> 0 | AZ14: =Template!$E38 -> 0 | BA14: =Template!$E39 -> 0 | BB14: =Template!$E40 -> 0 | BC14: =Template!$E41 -> 0 | BD14: =Template!$E42 -> 0 | BE14: =Template!$E43 -> 0 | BF14: =Template!$E44 -> 0 | BG14: =Template!$E45 -> 0 | BH14: =Template!$E46 -> 0 | BI14: =Template!$E47 -> 0 | BJ14: =Template!$E48 -> 0 | BK14: =Template!$E52 -> 0 | BL14: =Template!$E53 -> 0 | BM14: =Template!$E54 -> 0 | BN14: =Template!#REF! -> #REF! | BO14: =Template!#REF! -> #REF! | BP14: =Template!#REF! -> #REF! | BQ14: =Template!#REF! -> #REF! | BR14: =Template!#REF! -> #REF! | BS14: =Template!#REF! -> #REF! | BT14: =Template!#REF! -> #REF! | BU14: =Template!#REF! -> #REF! | ... CN14: =Template!#REF! -> #REF!
A15: =Template!#REF! -> #REF! | B15: =Template!#REF! -> #REF! | C15: =Template!#REF! -> #REF! | D15: =Template!$F1 -> 0 | E15: =Template!$F2 -> 0 | F15: =Template!$F3 -> 0 | G15: =Template!$F4 -> 0 | H15: =Template!$F5 -> 0 | I15: =Template!$F6 -> 0 | J15: =Template!$F7 -> 0 | K15: =Template!$F8 -> 0 | L15: =Template!$F9 -> 0 | M15: =Template!$F10 -> 0 | N15: =Template!$F11 -> 0 | O15: =Template!$F12 -> 0 | P15: =Template!$F13 -> 0 | Q15: =Template!$F17 -> 0 | R15: =Template!$F18 -> 0 | S15: =Template!$F19 -> 0 | T15: =Template!$F20 -> 0 | U15: =Template!$F21 -> 0 | V15: =Template!$F22 -> 0 | W15: =Template!#REF! -> #REF! | X15: =Template!#REF! -> #REF! | Y15: =Template!#REF! -> #REF! | Z15: =Template!#REF! -> #REF! | AA15: =Template!#REF! -> #REF! | AB15: =Template!#REF! -> #REF! | AC15: =Template!#REF! -> #REF! | AD15: =Template!#REF! -> #REF! | ... AH15: =Template!#REF! -> #REF! | AI15: =Template!$F28 -> 0 | AJ15: =Template!$F29 -> 0 | AK15: =Template!$F30 -> 0 | AL15: =Template!$F31 -> 0 | AM15: =Template!$F32 -> 0 | AN15: =Template!$F33 -> 0 | AO15: =Template!$F34 -> 0 | AP15: =Template!$F35 -> 0 | AQ15: =Template!#REF! -> #REF! | AR15: =Template!#REF! -> #REF! | AS15: =Template!#REF! -> #REF! | AT15: =Template!#REF! -> #REF! | AU15: =Template!#REF! -> #REF! | AV15: =Template!#REF! -> #REF! | AW15: =Template!#REF! -> #REF! | AX15: =Template!#REF! -> #REF! | AY15: =Template!$F37 -> 0 | AZ15: =Template!$F38 -> 0 | BA15: =Template!$F39 -> 0 | BB15: =Template!$F40 -> 0 | BC15: =Template!$F41 -> 0 | BD15: =Template!$F42 -> 0 | BE15: =Template!$F43 -> 0 | BF15: =Template!$F44 -> 0 | BG15: =Template!$F45 -> 0 | BH15: =Template!$F46 -> 0 | BI15: =Template!$F47 -> 0 | BJ15: =Template!$F48 -> 0 | BK15: =Template!$F52 -> 0 | BL15: =Template!$F53 -> 0 | BM15: =Template!$F54 -> 0 | BN15: =Template!#REF! -> #REF! | BO15: =Template!#REF! -> #REF! | BP15: =Template!#REF! -> #REF! | BQ15: =Template!#REF! -> #REF! | BR15: =Template!#REF! -> #REF! | BS15: =Template!#REF! -> #REF! | BT15: =Template!#REF! -> #REF! | BU15: =Template!#REF! -> #REF! | ... CN15: =Template!#REF! -> #REF!
A16: =Template!#REF! -> #REF! | B16: =Template!#REF! -> #REF! | C16: =Template!#REF! -> #REF! | D16: =Template!$G1 -> 0 | E16: =Template!$G2 -> 0 | F16: =Template!$G3 -> 0 | G16: =Template!$G4 -> 0 | H16: =Template!$G5 -> 0 | I16: =Template!$G6 -> 0 | J16: =Template!$G7 -> 0 | K16: =Template!$G8 -> 0 | L16: =Template!$G9 -> 0 | M16: =Template!$G10 -> 0 | N16: =Template!$G11 -> 0 | O16: =Template!$G12 -> 0 | P16: =Template!$G13 -> 0 | Q16: =Template!$G17 -> 0 | R16: =Template!$G18 -> 0 | S16: =Template!$G19 -> 0 | T16: =Template!$G20 -> 0 | U16: =Template!$G21 -> 0 | V16: =Template!$G22 -> 0 | W16: =Template!#REF! -> #REF! | X16: =Template!#REF! -> #REF! | Y16: =Template!#REF! -> #REF! | Z16: =Template!#REF! -> #REF! | AA16: =Template!#REF! -> #REF! | AB16: =Template!#REF! -> #REF! | AC16: =Template!#REF! -> #REF! | AD16: =Template!#REF! -> #REF! | ... AH16: =Template!#REF! -> #REF! | AI16: =Template!$G28 -> 0 | AJ16: =Template!$G29 -> 0 | AK16: =Template!$G30 -> 0 | AL16: =Template!$G31 -> 0 | AM16: =Template!$G32 -> 0 | AN16: =Template!$G33 -> 0 | AO16: =Template!$G34 -> 0 | AP16: =Template!$G35 -> 0 | AQ16: =Template!#REF! -> #REF! | AR16: =Template!#REF! -> #REF! | AS16: =Template!#REF! -> #REF! | AT16: =Template!#REF! -> #REF! | AU16: =Template!#REF! -> #REF! | AV16: =Template!#REF! -> #REF! | AW16: =Template!#REF! -> #REF! | AX16: =Template!#REF! -> #REF! | AY16: =Template!$G37 -> 0 | AZ16: =Template!$G38 -> 0 | BA16: =Template!$G39 -> 0 | BB16: =Template!$G40 -> 0 | BC16: =Template!$G41 -> 0 | BD16: =Template!$G42 -> 0 | BE16: =Template!$G43 -> 0 | BF16: =Template!$G44 -> 0 | BG16: =Template!$G45 -> 0 | BH16: =Template!$G46 -> 0 | BI16: =Template!$G47 -> 0 | BJ16: =Template!$G48 -> 0 | BK16: =Template!$G52 -> 0 | BL16: =Template!$G53 -> 0 | BM16: =Template!$G54 -> 0 | BN16: =Template!#REF! -> #REF! | BO16: =Template!#REF! -> #REF! | BP16: =Template!#REF! -> #REF! | BQ16: =Template!#REF! -> #REF! | BR16: =Template!#REF! -> #REF! | BS16: =Template!#REF! -> #REF! | BT16: =Template!#REF! -> #REF! | BU16: =Template!#REF! -> #REF! | ... CN16: =Template!#REF! -> #REF!
A17: =Template!#REF! -> #REF! | B17: =Template!#REF! -> #REF! | C17: =Template!#REF! -> #REF! | D17: =Template!$H1 -> 0 | E17: =Template!$H2 -> 0 | F17: =Template!$H3 -> 0 | G17: =Template!$H4 -> 0 | H17: =Template!$H5 -> 0 | I17: =Template!$H6 -> 0 | J17: =Template!$H7 -> 0 | K17: =Template!$H8 -> 0 | L17: =Template!$H9 -> 0 | M17: =Template!$H10 -> 0 | N17: =Template!$H11 -> 0 | O17: =Template!$H12 -> 0 | P17: =Template!$H13 -> 0 | Q17: =Template!$H17 -> 0 | R17: =Template!$H18 -> 0 | S17: =Template!$H19 -> 0 | T17: =Template!$H20 -> 0 | U17: =Template!$H21 -> 0 | V17: =Template!$H22 -> 0 | W17: =Template!#REF! -> #REF! | X17: =Template!#REF! -> #REF! | Y17: =Template!#REF! -> #REF! | Z17: =Template!#REF! -> #REF! | AA17: =Template!#REF! -> #REF! | AB17: =Template!#REF! -> #REF! | AC17: =Template!#REF! -> #REF! | AD17: =Template!#REF! -> #REF! | ... AH17: =Template!#REF! -> #REF! | AI17: =Template!$H28 -> 0 | AJ17: =Template!$H29 -> 0 | AK17: =Template!$H30 -> 0 | AL17: =Template!$H31 -> 0 | AM17: =Template!$H32 -> 0 | AN17: =Template!$H33 -> 0 | AO17: =Template!$H34 -> 0 | AP17: =Template!$H35 -> 0 | AQ17: =Template!#REF! -> #REF! | AR17: =Template!#REF! -> #REF! | AS17: =Template!#REF! -> #REF! | AT17: =Template!#REF! -> #REF! | AU17: =Template!#REF! -> #REF! | AV17: =Template!#REF! -> #REF! | AW17: =Template!#REF! -> #REF! | AX17: =Template!#REF! -> #REF! | AY17: =Template!$H37 -> 0 | AZ17: =Template!$H38 -> 0 | BA17: =Template!$H39 -> 0 | BB17: =Template!$H40 -> 0 | BC17: =Template!$H41 -> 0 | BD17: =Template!$H42 -> 0 | BE17: =Template!$H43 -> 0 | BF17: =Template!$H44 -> 0 | BG17: =Template!$H45 -> 0 | BH17: =Template!$H46 -> 0 | BI17: =Template!$H47 -> 0 | BJ17: =Template!$H48 -> 0 | BK17: =Template!$H52 -> 0 | BL17: =Template!$H53 -> 0 | BM17: =Template!$H54 -> 0 | BN17: =Template!#REF! -> #REF! | BO17: =Template!#REF! -> #REF! | BP17: =Template!#REF! -> #REF! | BQ17: =Template!#REF! -> #REF! | BR17: =Template!#REF! -> #REF! | BS17: =Template!#REF! -> #REF! | BT17: =Template!#REF! -> #REF! | BU17: =Template!#REF! -> #REF! | ... CN17: =Template!#REF! -> #REF!
A18: =Template!#REF! -> #REF! | B18: =Template!#REF! -> #REF! | C18: =Template!#REF! -> #REF! | D18: =Template!$I1 -> 0 | E18: =Template!$I2 -> 0 | F18: =Template!$I3 -> 0 | G18: =Template!$I4 -> 0 | H18: =Template!$I5 -> 0 | I18: =Template!$I6 -> 0 | J18: =Template!$I7 -> 0 | K18: =Template!$I8 -> 0 | L18: =Template!$I9 -> 0 | M18: =Template!$I10 -> 0 | N18: =Template!$I11 -> 0 | O18: =Template!$I12 -> 0 | P18: =Template!$I13 -> 0 | Q18: =Template!$I17 -> 0 | R18: =Template!$I18 -> 0 | S18: =Template!$I19 -> 0 | T18: =Template!$I20 -> 0 | U18: =Template!$I21 -> 0 | V18: =Template!$I22 -> 0 | W18: =Template!#REF! -> #REF! | X18: =Template!#REF! -> #REF! | Y18: =Template!#REF! -> #REF! | Z18: =Template!#REF! -> #REF! | AA18: =Template!#REF! -> #REF! | AB18: =Template!#REF! -> #REF! | AC18: =Template!#REF! -> #REF! | AD18: =Template!#REF! -> #REF! | ... AH18: =Template!#REF! -> #REF! | AI18: =Template!$I28 -> 0 | AJ18: =Template!$I29 -> 0 | AK18: =Template!$I30 -> 0 | AL18: =Template!$I31 -> 0 | AM18: =Template!$I32 -> 0 | AN18: =Template!$I33 -> 0 | AO18: =Template!$I34 -> 0 | AP18: =Template!$I35 -> 0 | AQ18: =Template!#REF! -> #REF! | AR18: =Template!#REF! -> #REF! | AS18: =Template!#REF! -> #REF! | AT18: =Template!#REF! -> #REF! | AU18: =Template!#REF! -> #REF! | AV18: =Template!#REF! -> #REF! | AW18: =Template!#REF! -> #REF! | AX18: =Template!#REF! -> #REF! | AY18: =Template!$I37 -> 0 | AZ18: =Template!$I38 -> 0 | BA18: =Template!$I39 -> 0 | BB18: =Template!$I40 -> 0 | BC18: =Template!$I41 -> 0 | BD18: =Template!$I42 -> 0 | BE18: =Template!$I43 -> 0 | BF18: =Template!$I44 -> 0 | BG18: =Template!$I45 -> 0 | BH18: =Template!$I46 -> 0 | BI18: =Template!$I47 -> 0 | BJ18: =Template!$I48 -> 0 | BK18: =Template!$I52 -> 0 | BL18: =Template!$I53 -> 0 | BM18: =Template!$I54 -> 0 | BN18: =Template!#REF! -> #REF! | BO18: =Template!#REF! -> #REF! | BP18: =Template!#REF! -> #REF! | BQ18: =Template!#REF! -> #REF! | BR18: =Template!#REF! -> #REF! | BS18: =Template!#REF! -> #REF! | BT18: =Template!#REF! -> #REF! | BU18: =Template!#REF! -> #REF! | ... CN18: =Template!#REF! -> #REF!
A19: =Template!#REF! -> #REF! | B19: =Template!#REF! -> #REF! | C19: =Template!#REF! -> #REF! | D19: =Template!$J1 -> 0 | E19: =Template!$J2 -> 0 | F19: =Template!$J3 -> 0 | G19: =Template!$J4 -> 0 | H19: =Template!$J5 -> 0 | I19: =Template!$J6 -> 0 | J19: =Template!$J7 -> 0 | K19: =Template!$J8 -> 0 | L19: =Template!$J9 -> 0 | M19: =Template!$J10 -> 0 | N19: =Template!$J11 -> 0 | O19: =Template!$J12 -> 0 | P19: =Template!$J13 -> 0 | Q19: =Template!$J17 -> 0 | R19: =Template!$J18 -> 0 | S19: =Template!$J19 -> 0 | T19: =Template!$J20 -> 0 | U19: =Template!$J21 -> 0 | V19: =Template!$J22 -> 0 | W19: =Template!#REF! -> #REF! | X19: =Template!#REF! -> #REF! | Y19: =Template!#REF! -> #REF! | Z19: =Template!#REF! -> #REF! | AA19: =Template!#REF! -> #REF! | AB19: =Template!#REF! -> #REF! | AC19: =Template!#REF! -> #REF! | AD19: =Template!#REF! -> #REF! | ... AH19: =Template!#REF! -> #REF! | AI19: =Template!$J28 -> 0 | AJ19: =Template!$J29 -> 0 | AK19: =Template!$J30 -> 0 | AL19: =Template!$J31 -> 0 | AM19: =Template!$J32 -> 0 | AN19: =Template!$J33 -> 0 | AO19: =Template!$J34 -> 0 | AP19: =Template!$J35 -> 0 | AQ19: =Template!#REF! -> #REF! | AR19: =Template!#REF! -> #REF! | AS19: =Template!#REF! -> #REF! | AT19: =Template!#REF! -> #REF! | AU19: =Template!#REF! -> #REF! | AV19: =Template!#REF! -> #REF! | AW19: =Template!#REF! -> #REF! | AX19: =Template!#REF! -> #REF! | AY19: =Template!$J37 -> 0 | AZ19: =Template!$J38 -> 0 | BA19: =Template!$J39 -> 0 | BB19: =Template!$J40 -> 0 | BC19: =Template!$J41 -> 0 | BD19: =Template!$J42 -> 0 | BE19: =Template!$J43 -> 0 | BF19: =Template!$J44 -> 0 | BG19: =Template!$J45 -> 0 | BH19: =Template!$J46 -> 0 | BI19: =Template!$J47 -> 0 | BJ19: =Template!$J48 -> 0 | BK19: =Template!$J52 -> 0 | BL19: =Template!$J53 -> 0 | BM19: =Template!$J54 -> 0 | BN19: =Template!#REF! -> #REF! | BO19: =Template!#REF! -> #REF! | BP19: =Template!#REF! -> #REF! | BQ19: =Template!#REF! -> #REF! | BR19: =Template!#REF! -> #REF! | BS19: =Template!#REF! -> #REF! | BT19: =Template!#REF! -> #REF! | BU19: =Template!#REF! -> #REF! | ... CN19: =Template!#REF! -> #REF!
A20: =Template!#REF! -> #REF! | B20: =Template!#REF! -> #REF! | C20: =Template!#REF! -> #REF! | D20: =Template!$K1 -> 0 | E20: =Template!$K2 -> 0 | F20: =Template!$K3 -> 0 | G20: =Template!$K4 -> 0 | H20: =Template!$K5 -> 0 | I20: =Template!$K6 -> 0 | J20: =Template!$K7 -> 0 | K20: =Template!$K8 -> 0 | L20: =Template!$K9 -> 0 | M20: =Template!$K10 -> 0 | N20: =Template!$K11 -> 0 | O20: =Template!$K12 -> 0 | P20: =Template!$K13 -> 0 | Q20: =Template!$K17 -> 0 | R20: =Template!$K18 -> 0 | S20: =Template!$K19 -> 0 | T20: =Template!$K20 -> 0 | U20: =Template!$K21 -> 0 | V20: =Template!$K22 -> 0 | W20: =Template!#REF! -> #REF! | X20: =Template!#REF! -> #REF! | Y20: =Template!#REF! -> #REF! | Z20: =Template!#REF! -> #REF! | AA20: =Template!#REF! -> #REF! | AB20: =Template!#REF! -> #REF! | AC20: =Template!#REF! -> #REF! | AD20: =Template!#REF! -> #REF! | ... AH20: =Template!#REF! -> #REF! | AI20: =Template!$K28 -> 0 | AJ20: =Template!$K29 -> 0 | AK20: =Template!$K30 -> 0 | AL20: =Template!$K31 -> 0 | AM20: =Template!$K32 -> 0 | AN20: =Template!$K33 -> 0 | AO20: =Template!$K34 -> 0 | AP20: =Template!$K35 -> 0 | AQ20: =Template!#REF! -> #REF! | AR20: =Template!#REF! -> #REF! | AS20: =Template!#REF! -> #REF! | AT20: =Template!#REF! -> #REF! | AU20: =Template!#REF! -> #REF! | AV20: =Template!#REF! -> #REF! | AW20: =Template!#REF! -> #REF! | AX20: =Template!#REF! -> #REF! | AY20: =Template!$K37 -> 0 | AZ20: =Template!$K38 -> 0 | BA20: =Template!$K39 -> 0 | BB20: =Template!$K40 -> 0 | BC20: =Template!$K41 -> 0 | BD20: =Template!$K42 -> 0 | BE20: =Template!$K43 -> 0 | BF20: =Template!$K44 -> 0 | BG20: =Template!$K45 -> 0 | BH20: =Template!$K46 -> 0 | BI20: =Template!$K47 -> 0 | BJ20: =Template!$K48 -> 0 | BK20: =Template!$K52 -> 0 | BL20: =Template!$K53 -> 0 | BM20: =Template!$K54 -> 0 | BN20: =Template!#REF! -> #REF! | BO20: =Template!#REF! -> #REF! | BP20: =Template!#REF! -> #REF! | BQ20: =Template!#REF! -> #REF! | BR20: =Template!#REF! -> #REF! | BS20: =Template!#REF! -> #REF! | BT20: =Template!#REF! -> #REF! | BU20: =Template!#REF! -> #REF! | ... CN20: =Template!#REF! -> #REF!
A21: =Template!#REF! -> #REF! | B21: =Template!#REF! -> #REF! | C21: =Template!#REF! -> #REF! | D21: =Template!$L1 -> 0 | E21: =Template!$L2 -> 0 | F21: =Template!$L3 -> 0 | G21: =Template!$L4 -> 0 | H21: =Template!$L5 -> 0 | I21: =Template!$L6 -> 0 | J21: =Template!$L7 -> 0 | K21: =Template!$L8 -> 0 | L21: =Template!$L9 -> 0 | M21: =Template!$L10 -> 0 | N21: =Template!$L11 -> 0 | O21: =Template!$L12 -> 0 | P21: =Template!$L13 -> 0 | Q21: =Template!$L17 -> 0 | R21: =Template!$L18 -> 0 | S21: =Template!$L19 -> 0 | T21: =Template!$L20 -> 0 | U21: =Template!$L21 -> 0 | V21: =Template!$L22 -> 0 | W21: =Template!#REF! -> #REF! | X21: =Template!#REF! -> #REF! | Y21: =Template!#REF! -> #REF! | Z21: =Template!#REF! -> #REF! | AA21: =Template!#REF! -> #REF! | AB21: =Template!#REF! -> #REF! | AC21: =Template!#REF! -> #REF! | AD21: =Template!#REF! -> #REF! | ... AH21: =Template!#REF! -> #REF! | AI21: =Template!$L28 -> 0 | AJ21: =Template!$L29 -> 0 | AK21: =Template!$L30 -> 0 | AL21: =Template!$L31 -> 0 | AM21: =Template!$L32 -> 0 | AN21: =Template!$L33 -> 0 | AO21: =Template!$L34 -> 0 | AP21: =Template!$L35 -> 0 | AQ21: =Template!#REF! -> #REF! | AR21: =Template!#REF! -> #REF! | AS21: =Template!#REF! -> #REF! | AT21: =Template!#REF! -> #REF! | AU21: =Template!#REF! -> #REF! | AV21: =Template!#REF! -> #REF! | AW21: =Template!#REF! -> #REF! | AX21: =Template!#REF! -> #REF! | AY21: =Template!$L37 -> 0 | AZ21: =Template!$L38 -> 0 | BA21: =Template!$L39 -> 0 | BB21: =Template!$L40 -> 0 | BC21: =Template!$L41 -> 0 | BD21: =Template!$L42 -> 0 | BE21: =Template!$L43 -> 0 | BF21: =Template!$L44 -> 0 | BG21: =Template!$L45 -> 0 | BH21: =Template!$L46 -> 0 | BI21: =Template!$L47 -> 0 | BJ21: =Template!$L48 -> 0 | BK21: =Template!$L52 -> 0 | BL21: =Template!$L53 -> 0 | BM21: =Template!$L54 -> 0 | BN21: =Template!#REF! -> #REF! | BO21: =Template!#REF! -> #REF! | BP21: =Template!#REF! -> #REF! | BQ21: =Template!#REF! -> #REF! | BR21: =Template!#REF! -> #REF! | BS21: =Template!#REF! -> #REF! | BT21: =Template!#REF! -> #REF! | BU21: =Template!#REF! -> #REF! | ... CN21: =Template!#REF! -> #REF!
A22: =Template!#REF! -> #REF! | B22: =Template!#REF! -> #REF! | C22: =Template!#REF! -> #REF! | D22: =Template!$M1 -> 0 | E22: =Template!$M2 -> 0 | F22: =Template!$M3 -> 0 | G22: =Template!$M4 -> 0 | H22: =Template!$M5 -> 0 | I22: =Template!$M6 -> 0 | J22: =Template!$M7 -> 0 | K22: =Template!$M8 -> 0 | L22: =Template!$M9 -> 0 | M22: =Template!$M10 -> 0 | N22: =Template!$M11 -> 0 | O22: =Template!$M12 -> 0 | P22: =Template!$M13 -> 0 | Q22: =Template!$M17 -> 0 | R22: =Template!$M18 -> 0 | S22: =Template!$M19 -> 0 | T22: =Template!$M20 -> 0 | U22: =Template!$M21 -> 0 | V22: =Template!$M22 -> 0 | W22: =Template!#REF! -> #REF! | X22: =Template!#REF! -> #REF! | Y22: =Template!#REF! -> #REF! | Z22: =Template!#REF! -> #REF! | AA22: =Template!#REF! -> #REF! | AB22: =Template!#REF! -> #REF! | AC22: =Template!#REF! -> #REF! | AD22: =Template!#REF! -> #REF! | ... AH22: =Template!#REF! -> #REF! | AI22: =Template!$M28 -> 0 | AJ22: =Template!$M29 -> 0 | AK22: =Template!$M30 -> 0 | AL22: =Template!$M31 -> 0 | AM22: =Template!$M32 -> 0 | AN22: =Template!$M33 -> 0 | AO22: =Template!$M34 -> 0 | AP22: =Template!$M35 -> 0 | AQ22: =Template!#REF! -> #REF! | AR22: =Template!#REF! -> #REF! | AS22: =Template!#REF! -> #REF! | AT22: =Template!#REF! -> #REF! | AU22: =Template!#REF! -> #REF! | AV22: =Template!#REF! -> #REF! | AW22: =Template!#REF! -> #REF! | AX22: =Template!#REF! -> #REF! | AY22: =Template!$M37 -> 0 | AZ22: =Template!$M38 -> 0 | BA22: =Template!$M39 -> 0 | BB22: =Template!$M40 -> 0 | BC22: =Template!$M41 -> 0 | BD22: =Template!$M42 -> 0 | BE22: =Template!$M43 -> 0 | BF22: =Template!$M44 -> 0 | BG22: =Template!$M45 -> 0 | BH22: =Template!$M46 -> 0 | BI22: =Template!$M47 -> 0 | BJ22: =Template!$M48 -> 0 | BK22: =Template!$M52 -> 0 | BL22: =Template!$M53 -> 0 | BM22: =Template!$M54 -> 0 | BN22: =Template!#REF! -> #REF! | BO22: =Template!#REF! -> #REF! | BP22: =Template!#REF! -> #REF! | BQ22: =Template!#REF! -> #REF! | BR22: =Template!#REF! -> #REF! | BS22: =Template!#REF! -> #REF! | BT22: =Template!#REF! -> #REF! | BU22: =Template!#REF! -> #REF! | ... CN22: =Template!#REF! -> #REF!
A23: =Template!#REF! -> #REF! | B23: =Template!#REF! -> #REF! | C23: =Template!#REF! -> #REF! | D23: =Template!$N1 -> 0 | E23: =Template!$N2 -> 0 | F23: =Template!$N3 -> 0 | G23: =Template!$N4 -> 0 | H23: =Template!$N5 -> 0 | I23: =Template!$N6 -> 0 | J23: =Template!$N7 -> 0 | K23: =Template!$N8 -> 0 | L23: =Template!$N9 -> 0 | M23: =Template!$N10 -> 0 | N23: =Template!$N11 -> 0 | O23: =Template!$N12 -> 0 | P23: =Template!$N13 -> 0 | Q23: =Template!$N17 -> 0 | R23: =Template!$N18 -> 0 | S23: =Template!$N19 -> 0 | T23: =Template!$N20 -> 0 | U23: =Template!$N21 -> 0 | V23: =Template!$N22 -> 0 | W23: =Template!#REF! -> #REF! | X23: =Template!#REF! -> #REF! | Y23: =Template!#REF! -> #REF! | Z23: =Template!#REF! -> #REF! | AA23: =Template!#REF! -> #REF! | AB23: =Template!#REF! -> #REF! | AC23: =Template!#REF! -> #REF! | AD23: =Template!#REF! -> #REF! | ... AH23: =Template!#REF! -> #REF! | AI23: =Template!$N28 -> 0 | AJ23: =Template!$N29 -> 0 | AK23: =Template!$N30 -> 0 | AL23: =Template!$N31 -> 0 | AM23: =Template!$N32 -> 0 | AN23: =Template!$N33 -> 0 | AO23: =Template!$N34 -> 0 | AP23: =Template!$N35 -> 0 | AQ23: =Template!#REF! -> #REF! | AR23: =Template!#REF! -> #REF! | AS23: =Template!#REF! -> #REF! | AT23: =Template!#REF! -> #REF! | AU23: =Template!#REF! -> #REF! | AV23: =Template!#REF! -> #REF! | AW23: =Template!#REF! -> #REF! | AX23: =Template!#REF! -> #REF! | AY23: =Template!$N37 -> 0 | AZ23: =Template!$N38 -> 0 | BA23: =Template!$N39 -> 0 | BB23: =Template!$N40 -> 0 | BC23: =Template!$N41 -> 0 | BD23: =Template!$N42 -> 0 | BE23: =Template!$N43 -> 0 | BF23: =Template!$N44 -> 0 | BG23: =Template!$N45 -> 0 | BH23: =Template!$N46 -> 0 | BI23: =Template!$N47 -> 0 | BJ23: =Template!$N48 -> 0 | BK23: =Template!$N52 -> 0 | BL23: =Template!$N53 -> 0 | BM23: =Template!$N54 -> 0 | BN23: =Template!#REF! -> #REF! | BO23: =Template!#REF! -> #REF! | BP23: =Template!#REF! -> #REF! | BQ23: =Template!#REF! -> #REF! | BR23: =Template!#REF! -> #REF! | BS23: =Template!#REF! -> #REF! | BT23: =Template!#REF! -> #REF! | BU23: =Template!#REF! -> #REF! | ... CN23: =Template!#REF! -> #REF!
A24: =Template!#REF! -> #REF! | B24: =Template!#REF! -> #REF! | C24: =Template!#REF! -> #REF! | D24: =Template!$O1 -> 0 | E24: =Template!$O2 -> 0 | F24: =Template!$O3 -> 0 | G24: =Template!$O4 -> 0 | H24: =Template!$O5 -> 0 | I24: =Template!$O6 -> 0 | J24: =Template!$O7 -> 0 | K24: =Template!$O8 -> 0 | L24: =Template!$O9 -> 0 | M24: =Template!$O10 -> 0 | N24: =Template!$O11 -> 0 | O24: =Template!$O12 -> 0 | P24: =Template!$O13 -> 0 | Q24: =Template!$O17 -> 0 | R24: =Template!$O18 -> 0 | S24: =Template!$O19 -> 0 | T24: =Template!$O20 -> 0 | U24: =Template!$O21 -> 0 | V24: =Template!$O22 -> 0 | W24: =Template!#REF! -> #REF! | X24: =Template!#REF! -> #REF! | Y24: =Template!#REF! -> #REF! | Z24: =Template!#REF! -> #REF! | AA24: =Template!#REF! -> #REF! | AB24: =Template!#REF! -> #REF! | AC24: =Template!#REF! -> #REF! | AD24: =Template!#REF! -> #REF! | ... AH24: =Template!#REF! -> #REF! | AI24: =Template!$O28 -> 0 | AJ24: =Template!$O29 -> 0 | AK24: =Template!$O30 -> 0 | AL24: =Template!$O31 -> 0 | AM24: =Template!$O32 -> 0 | AN24: =Template!$O33 -> 0 | AO24: =Template!$O34 -> 0 | AP24: =Template!$O35 -> 0 | AQ24: =Template!#REF! -> #REF! | AR24: =Template!#REF! -> #REF! | AS24: =Template!#REF! -> #REF! | AT24: =Template!#REF! -> #REF! | AU24: =Template!#REF! -> #REF! | AV24: =Template!#REF! -> #REF! | AW24: =Template!#REF! -> #REF! | AX24: =Template!#REF! -> #REF! | AY24: =Template!$O37 -> 0 | AZ24: =Template!$O38 -> 0 | BA24: =Template!$O39 -> 0 | BB24: =Template!$O40 -> 0 | BC24: =Template!$O41 -> 0 | BD24: =Template!$O42 -> 0 | BE24: =Template!$O43 -> 0 | BF24: =Template!$O44 -> 0 | BG24: =Template!$O45 -> 0 | BH24: =Template!$O46 -> 0 | BI24: =Template!$O47 -> 0 | BJ24: =Template!$O48 -> 0 | BK24: =Template!$O52 -> 0 | BL24: =Template!$O53 -> 0 | BM24: =Template!$O54 -> 0 | BN24: =Template!#REF! -> #REF! | BO24: =Template!#REF! -> #REF! | BP24: =Template!#REF! -> #REF! | BQ24: =Template!#REF! -> #REF! | BR24: =Template!#REF! -> #REF! | BS24: =Template!#REF! -> #REF! | BT24: =Template!#REF! -> #REF! | BU24: =Template!#REF! -> #REF! | ... CN24: =Template!#REF! -> #REF!
A25: =Template!#REF! -> #REF! | B25: =Template!#REF! -> #REF! | C25: =Template!#REF! -> #REF! | D25: =Template!$P1 -> 0 | E25: =Template!$P2 -> 0 | F25: =Template!$P3 -> 0 | G25: =Template!$P4 -> 0 | H25: =Template!$P5 -> 0 | I25: =Template!$P6 -> 0 | J25: =Template!$P7 -> 0 | K25: =Template!$P8 -> 0 | L25: =Template!$P9 -> 0 | M25: =Template!$P10 -> 0 | N25: =Template!$P11 -> 0 | O25: =Template!$P12 -> 0 | P25: =Template!$P13 -> 0 | Q25: =Template!$P17 -> 0 | R25: =Template!$P18 -> 0 | S25: =Template!$P19 -> 0 | T25: =Template!$P20 -> 0 | U25: =Template!$P21 -> 0 | V25: =Template!$P22 -> 0 | W25: =Template!#REF! -> #REF! | X25: =Template!#REF! -> #REF! | Y25: =Template!#REF! -> #REF! | Z25: =Template!#REF! -> #REF! | AA25: =Template!#REF! -> #REF! | AB25: =Template!#REF! -> #REF! | AC25: =Template!#REF! -> #REF! | AD25: =Template!#REF! -> #REF! | ... AH25: =Template!#REF! -> #REF! | AI25: =Template!$P28 -> 0 | AJ25: =Template!$P29 -> 0 | AK25: =Template!$P30 -> 0 | AL25: =Template!$P31 -> 0 | AM25: =Template!$P32 -> 0 | AN25: =Template!$P33 -> 0 | AO25: =Template!$P34 -> 0 | AP25: =Template!$P35 -> 0 | AQ25: =Template!#REF! -> #REF! | AR25: =Template!#REF! -> #REF! | AS25: =Template!#REF! -> #REF! | AT25: =Template!#REF! -> #REF! | AU25: =Template!#REF! -> #REF! | AV25: =Template!#REF! -> #REF! | AW25: =Template!#REF! -> #REF! | AX25: =Template!#REF! -> #REF! | AY25: =Template!$P37 -> 0 | AZ25: =Template!$P38 -> 0 | BA25: =Template!$P39 -> 0 | BB25: =Template!$P40 -> 0 | BC25: =Template!$P41 -> 0 | BD25: =Template!$P42 -> 0 | BE25: =Template!$P43 -> 0 | BF25: =Template!$P44 -> 0 | BG25: =Template!$P45 -> 0 | BH25: =Template!$P46 -> 0 | BI25: =Template!$P47 -> 0 | BJ25: =Template!$P48 -> 0 | BK25: =Template!$P52 -> 0 | BL25: =Template!$P53 -> 0 | BM25: =Template!$P54 -> 0 | BN25: =Template!#REF! -> #REF! | BO25: =Template!#REF! -> #REF! | BP25: =Template!#REF! -> #REF! | BQ25: =Template!#REF! -> #REF! | BR25: =Template!#REF! -> #REF! | BS25: =Template!#REF! -> #REF! | BT25: =Template!#REF! -> #REF! | BU25: =Template!#REF! -> #REF! | ... CN25: =Template!#REF! -> #REF!
A26: =Template!#REF! -> #REF! | B26: =Template!#REF! -> #REF! | C26: =Template!#REF! -> #REF! | D26: =Template!$Q1 -> 0 | E26: =Template!$Q2 -> 0 | F26: =Template!$Q3 -> 0 | G26: =Template!$Q4 -> 0 | H26: =Template!$Q5 -> 0 | I26: =Template!$Q6 -> 0 | J26: =Template!$Q7 -> 0 | K26: =Template!$Q8 -> 0 | L26: =Template!$Q9 -> 0 | M26: =Template!$Q10 -> 0 | N26: =Template!$Q11 -> 0 | O26: =Template!$Q12 -> 0 | P26: =Template!$Q13 -> 0 | Q26: =Template!$Q17 -> 0 | R26: =Template!$Q18 -> 0 | S26: =Template!$Q19 -> 0 | T26: =Template!$Q20 -> 0 | U26: =Template!$Q21 -> 0 | V26: =Template!$Q22 -> 0 | W26: =Template!#REF! -> #REF! | X26: =Template!#REF! -> #REF! | Y26: =Template!#REF! -> #REF! | Z26: =Template!#REF! -> #REF! | AA26: =Template!#REF! -> #REF! | AB26: =Template!#REF! -> #REF! | AC26: =Template!#REF! -> #REF! | AD26: =Template!#REF! -> #REF! | ... AH26: =Template!#REF! -> #REF! | AI26: =Template!$Q28 -> 0 | AJ26: =Template!$Q29 -> 0 | AK26: =Template!$Q30 -> 0 | AL26: =Template!$Q31 -> 0 | AM26: =Template!$Q32 -> 0 | AN26: =Template!$Q33 -> 0 | AO26: =Template!$Q34 -> 0 | AP26: =Template!$Q35 -> 0 | AQ26: =Template!#REF! -> #REF! | AR26: =Template!#REF! -> #REF! | AS26: =Template!#REF! -> #REF! | AT26: =Template!#REF! -> #REF! | AU26: =Template!#REF! -> #REF! | AV26: =Template!#REF! -> #REF! | AW26: =Template!#REF! -> #REF! | AX26: =Template!#REF! -> #REF! | AY26: =Template!$Q37 -> 0 | AZ26: =Template!$Q38 -> 0 | BA26: =Template!$Q39 -> 0 | BB26: =Template!$Q40 -> 0 | BC26: =Template!$Q41 -> 0 | BD26: =Template!$Q42 -> 0 | BE26: =Template!$Q43 -> 0 | BF26: =Template!$Q44 -> 0 | BG26: =Template!$Q45 -> 0 | BH26: =Template!$Q46 -> 0 | BI26: =Template!$Q47 -> 0 | BJ26: =Template!$Q48 -> 0 | BK26: =Template!$Q52 -> 0 | BL26: =Template!$Q53 -> 0 | BM26: =Template!$Q54 -> 0 | BN26: =Template!#REF! -> #REF! | BO26: =Template!#REF! -> #REF! | BP26: =Template!#REF! -> #REF! | BQ26: =Template!#REF! -> #REF! | BR26: =Template!#REF! -> #REF! | BS26: =Template!#REF! -> #REF! | BT26: =Template!#REF! -> #REF! | BU26: =Template!#REF! -> #REF! | ... CN26: =Template!#REF! -> #REF!
A27: =Template!#REF! -> #REF! | B27: =Template!#REF! -> #REF! | C27: =Template!#REF! -> #REF! | D27: =Template!$R$1 -> 0 | E27: =Template!$R$2 -> 0 | F27: =Template!$R$3 -> 0 | G27: =Template!$R$4 -> 0 | H27: =Template!$R$5 -> 0 | I27: =Template!$R$6 -> 0 | J27: =Template!$R$7 -> 0 | K27: =Template!$R$8 -> 0 | L27: =Template!$R$9 -> 0 | M27: =Template!$R$10 -> 0 | N27: =Template!$R$11 -> 0 | O27: =Template!$R$12 -> 0 | P27: =Template!$R$13 -> 0 | Q27: =Template!$R$17 -> 0 | R27: =Template!$R$18 -> 0 | S27: =Template!$R$19 -> 0 | T27: =Template!$R$20 -> 0 | U27: =Template!$R$21 -> 0 | V27: =Template!$R$22 -> 0 | W27: =Template!#REF! -> #REF! | X27: =Template!#REF! -> #REF! | Y27: =Template!#REF! -> #REF! | Z27: =Template!#REF! -> #REF! | AA27: =Template!#REF! -> #REF! | AB27: =Template!#REF! -> #REF! | AC27: =Template!#REF! -> #REF! | AD27: =Template!#REF! -> #REF! | ... AH27: =Template!#REF! -> #REF! | AI27: =Template!$R$28 -> 0 | AJ27: =Template!$R$29 -> 0 | AK27: =Template!$R$30 -> 0 | AL27: =Template!$R$31 -> 0 | AM27: =Template!$R$32 -> 0 | AN27: =Template!$R$33 -> 0 | AO27: =Template!$R$34 -> 0 | AP27: =Template!$R$35 -> 0 | AQ27: =Template!#REF! -> #REF! | AR27: =Template!#REF! -> #REF! | AS27: =Template!#REF! -> #REF! | AT27: =Template!#REF! -> #REF! | AU27: =Template!#REF! -> #REF! | AV27: =Template!#REF! -> #REF! | AW27: =Template!#REF! -> #REF! | AX27: =Template!#REF! -> #REF! | AY27: =Template!$R$37 -> 0 | AZ27: =Template!$R$38 -> 0 | BA27: =Template!$R$39 -> 0 | BB27: =Template!$R$40 -> 0 | BC27: =Template!$R$41 -> 0 | BD27: =Template!$R$42 -> 0 | BE27: =Template!$R$43 -> 0 | BF27: =Template!$R$44 -> 0 | BG27: =Template!$R$45 -> 0 | BH27: =Template!$R$46 -> 0 | BI27: =Template!$R$47 -> 0 | BJ27: =Template!$R$48 -> 0 | BK27: =Template!$R$52 -> 0 | BL27: =Template!$R$53 -> 0 | BM27: =Template!$R$54 -> 0 | BN27: =Template!#REF! -> #REF! | BO27: =Template!#REF! -> #REF! | BP27: =Template!#REF! -> #REF! | BQ27: =Template!#REF! -> #REF! | BR27: =Template!#REF! -> #REF! | BS27: =Template!#REF! -> #REF! | BT27: =Template!#REF! -> #REF! | BU27: =Template!#REF! -> #REF! | ... CN27: =Template!#REF! -> #REF!
A28: =Template!#REF! -> #REF! | B28: =Template!#REF! -> #REF! | C28: =Template!#REF! -> #REF! | D28: =Template!$S$1 -> 0 | E28: =Template!$S$2 -> 0 | F28: =Template!$S$3 -> 0 | G28: =Template!$S$4 -> 0 | H28: =Template!$S$5 -> 0 | I28: =Template!$S$6 -> 0 | J28: =Template!$S$7 -> 0 | K28: =Template!$S$8 -> 0 | L28: =Template!$S$9 -> 0 | M28: =Template!$S$10 -> 0 | N28: =Template!$S$11 -> 0 | O28: =Template!$S$12 -> 0 | P28: =Template!$S$13 -> 0 | Q28: =Template!$S$17 -> 0 | R28: =Template!$S$18 -> 0 | S28: =Template!$S$19 -> 0 | T28: =Template!$S$20 -> 0 | U28: =Template!$S$21 -> 0 | V28: =Template!$S$22 -> 0 | W28: =Template!#REF! -> #REF! | X28: =Template!#REF! -> #REF! | Y28: =Template!#REF! -> #REF! | Z28: =Template!#REF! -> #REF! | AA28: =Template!#REF! -> #REF! | AB28: =Template!#REF! -> #REF! | AC28: =Template!#REF! -> #REF! | AD28: =Template!#REF! -> #REF! | ... AH28: =Template!#REF! -> #REF! | AI28: =Template!$S$28 -> 0 | AJ28: =Template!$S$29 -> 0 | AK28: =Template!$S$30 -> 0 | AL28: =Template!$S$31 -> 0 | AM28: =Template!$S$32 -> 0 | AN28: =Template!$S$33 -> 0 | AO28: =Template!$S$34 -> 0 | AP28: =Template!$S$35 -> 0 | AQ28: =Template!#REF! -> #REF! | AR28: =Template!#REF! -> #REF! | AS28: =Template!#REF! -> #REF! | AT28: =Template!#REF! -> #REF! | AU28: =Template!#REF! -> #REF! | AV28: =Template!#REF! -> #REF! | AW28: =Template!#REF! -> #REF! | AX28: =Template!#REF! -> #REF! | AY28: =Template!$S$37 -> 0 | AZ28: =Template!$S$38 -> 0 | BA28: =Template!$S$39 -> 0 | BB28: =Template!$S$40 -> 0 | BC28: =Template!$S$41 -> 0 | BD28: =Template!$S$42 -> 0 | BE28: =Template!$S$43 -> 0 | BF28: =Template!$S$44 -> 0 | BG28: =Template!$S$45 -> 0 | BH28: =Template!$S$46 -> 0 | BI28: =Template!$S$47 -> 0 | BJ28: =Template!$S$48 -> 0 | BK28: =Template!$S$52 -> 0 | BL28: =Template!$S$53 -> 0 | BM28: =Template!$S$54 -> 0 | BN28: =Template!#REF! -> #REF! | BO28: =Template!#REF! -> #REF! | BP28: =Template!#REF! -> #REF! | BQ28: =Template!#REF! -> #REF! | BR28: =Template!#REF! -> #REF! | BS28: =Template!#REF! -> #REF! | BT28: =Template!#REF! -> #REF! | BU28: =Template!#REF! -> #REF! | ... CN28: =Template!#REF! -> #REF!
A29: =Template!#REF! -> #REF! | B29: =Template!#REF! -> #REF! | C29: =Template!#REF! -> #REF! | D29: =Template!$T$1 -> 0 | E29: =Template!$T$2 -> 0 | F29: =Template!$T$3 -> 0 | G29: =Template!$T$4 -> 0 | H29: =Template!$T$5 -> 0 | I29: =Template!$T$6 -> 0 | J29: =Template!$T$7 -> 0 | K29: =Template!$T$8 -> 0 | L29: =Template!$T$9 -> 0 | M29: =Template!$T$10 -> 0 | N29: =Template!$T$11 -> 0 | O29: =Template!$T$12 -> 0 | P29: =Template!$T$13 -> 0 | Q29: =Template!$T$17 -> 0 | R29: =Template!$T$18 -> 0 | S29: =Template!$T$19 -> 0 | T29: =Template!$T$20 -> 0 | U29: =Template!$T$21 -> 0 | V29: =Template!$T$22 -> 0 | W29: =Template!#REF! -> #REF! | X29: =Template!#REF! -> #REF! | Y29: =Template!#REF! -> #REF! | Z29: =Template!#REF! -> #REF! | AA29: =Template!#REF! -> #REF! | AB29: =Template!#REF! -> #REF! | AC29: =Template!#REF! -> #REF! | AD29: =Template!#REF! -> #REF! | ... AH29: =Template!#REF! -> #REF! | AI29: =Template!$T$28 -> 0 | AJ29: =Template!$T$29 -> 0 | AK29: =Template!$T$30 -> 0 | AL29: =Template!$T$31 -> 0 | AM29: =Template!$T$32 -> 0 | AN29: =Template!$T$33 -> 0 | AO29: =Template!$T$34 -> 0 | AP29: =Template!$T$35 -> 0 | AQ29: =Template!#REF! -> #REF! | AR29: =Template!#REF! -> #REF! | AS29: =Template!#REF! -> #REF! | AT29: =Template!#REF! -> #REF! | AU29: =Template!#REF! -> #REF! | AV29: =Template!#REF! -> #REF! | AW29: =Template!#REF! -> #REF! | AX29: =Template!#REF! -> #REF! | AY29: =Template!$T$37 -> 0 | AZ29: =Template!$T$38 -> 0 | BA29: =Template!$T$39 -> 0 | BB29: =Template!$T$40 -> 0 | BC29: =Template!$T$41 -> 0 | BD29: =Template!$T$42 -> 0 | BE29: =Template!$T$43 -> 0 | BF29: =Template!$T$44 -> 0 | BG29: =Template!$T$45 -> 0 | BH29: =Template!$T$46 -> 0 | BI29: =Template!$T$47 -> 0 | BJ29: =Template!$T$48 -> 0 | BK29: =Template!$T$52 -> 0 | BL29: =Template!$T$53 -> 0 | BM29: =Template!$T$54 -> 0 | BN29: =Template!#REF! -> #REF! | BO29: =Template!#REF! -> #REF! | BP29: =Template!#REF! -> #REF! | BQ29: =Template!#REF! -> #REF! | BR29: =Template!#REF! -> #REF! | BS29: =Template!#REF! -> #REF! | BT29: =Template!#REF! -> #REF! | BU29: =Template!#REF! -> #REF! | ... CN29: =Template!#REF! -> #REF!
A30: =Template!#REF! -> #REF! | B30: =Template!#REF! -> #REF! | C30: =Template!#REF! -> #REF! | D30: =Template!$U$1 -> 0 | E30: =Template!$U$2 -> 0 | F30: =Template!$U$3 -> 0 | G30: =Template!$U$4 -> 0 | H30: =Template!$U$5 -> 0 | I30: =Template!$U$6 -> 0 | J30: =Template!$U$7 -> 0 | K30: =Template!$U$8 -> 0 | L30: =Template!$U$9 -> 0 | M30: =Template!$U$10 -> 0 | N30: =Template!$U$11 -> 0 | O30: =Template!$U$12 -> 0 | P30: =Template!$U$13 -> 0 | Q30: =Template!$U$17 -> 0 | R30: =Template!$U$18 -> 0 | S30: =Template!$U$19 -> 0 | T30: =Template!$U$20 -> 0 | U30: =Template!$U$21 -> 0 | V30: =Template!$U$22 -> 0 | W30: =Template!#REF! -> #REF! | X30: =Template!#REF! -> #REF! | Y30: =Template!#REF! -> #REF! | Z30: =Template!#REF! -> #REF! | AA30: =Template!#REF! -> #REF! | AB30: =Template!#REF! -> #REF! | AC30: =Template!#REF! -> #REF! | AD30: =Template!#REF! -> #REF! | ... AH30: =Template!#REF! -> #REF! | AI30: =Template!$U$28 -> 0 | AJ30: =Template!$U$29 -> 0 | AK30: =Template!$U$30 -> 0 | AL30: =Template!$U$31 -> 0 | AM30: =Template!$U$32 -> 0 | AN30: =Template!$U$33 -> 0 | AO30: =Template!$U$34 -> 0 | AP30: =Template!$U$35 -> 0 | AQ30: =Template!#REF! -> #REF! | AR30: =Template!#REF! -> #REF! | AS30: =Template!#REF! -> #REF! | AT30: =Template!#REF! -> #REF! | AU30: =Template!#REF! -> #REF! | AV30: =Template!#REF! -> #REF! | AW30: =Template!#REF! -> #REF! | AX30: =Template!#REF! -> #REF! | AY30: =Template!$U$37 -> 0 | AZ30: =Template!$U$38 -> 0 | BA30: =Template!$U$39 -> 0 | BB30: =Template!$U$40 -> 0 | BC30: =Template!$U$41 -> 0 | BD30: =Template!$U$42 -> 0 | BE30: =Template!$U$43 -> 0 | BF30: =Template!$U$44 -> 0 | BG30: =Template!$U$45 -> 0 | BH30: =Template!$U$46 -> 0 | BI30: =Template!$U$47 -> 0 | BJ30: =Template!$U$48 -> 0 | BK30: =Template!$U$52 -> 0 | BL30: =Template!$U$53 -> 0 | BM30: =Template!$U$54 -> 0 | BN30: =Template!#REF! -> #REF! | BO30: =Template!#REF! -> #REF! | BP30: =Template!#REF! -> #REF! | BQ30: =Template!#REF! -> #REF! | BR30: =Template!#REF! -> #REF! | BS30: =Template!#REF! -> #REF! | BT30: =Template!#REF! -> #REF! | BU30: =Template!#REF! -> #REF! | ... CN30: =Template!#REF! -> #REF!
A31: =Template!#REF! -> #REF! | B31: =Template!#REF! -> #REF! | C31: =Template!#REF! -> #REF! | D31: =Template!$V$1 -> 0 | E31: =Template!$V$2 -> 0 | F31: =Template!$V$3 -> 0 | G31: =Template!$V$4 -> 0 | H31: =Template!$V$5 -> 0 | I31: =Template!$V$6 -> 0 | J31: =Template!$V$7 -> 0 | K31: =Template!$V$8 -> 0 | L31: =Template!$V$9 -> 0 | M31: =Template!$V$10 -> 0 | N31: =Template!$V$11 -> 0 | O31: =Template!$V$12 -> 0 | P31: =Template!$V$13 -> 0 | Q31: =Template!$V$17 -> 0 | R31: =Template!$V$18 -> 0 | S31: =Template!$V$19 -> 0 | T31: =Template!$V$20 -> 0 | U31: =Template!$V$21 -> 0 | V31: =Template!$V$22 -> 0 | W31: =Template!#REF! -> #REF! | X31: =Template!#REF! -> #REF! | Y31: =Template!#REF! -> #REF! | Z31: =Template!#REF! -> #REF! | AA31: =Template!#REF! -> #REF! | AB31: =Template!#REF! -> #REF! | AC31: =Template!#REF! -> #REF! | AD31: =Template!#REF! -> #REF! | ... AH31: =Template!#REF! -> #REF! | AI31: =Template!$V$28 -> 0 | AJ31: =Template!$V$29 -> 0 | AK31: =Template!$V$30 -> 0 | AL31: =Template!$V$31 -> 0 | AM31: =Template!$V$32 -> 0 | AN31: =Template!$V$33 -> 0 | AO31: =Template!$V$34 -> 0 | AP31: =Template!$V$35 -> 0 | AQ31: =Template!#REF! -> #REF! | AR31: =Template!#REF! -> #REF! | AS31: =Template!#REF! -> #REF! | AT31: =Template!#REF! -> #REF! | AU31: =Template!#REF! -> #REF! | AV31: =Template!#REF! -> #REF! | AW31: =Template!#REF! -> #REF! | AX31: =Template!#REF! -> #REF! | AY31: =Template!$V$37 -> 0 | AZ31: =Template!$V$38 -> 0 | BA31: =Template!$V$39 -> 0 | BB31: =Template!$V$40 -> 0 | BC31: =Template!$V$41 -> 0 | BD31: =Template!$V$42 -> 0 | BE31: =Template!$V$43 -> 0 | BF31: =Template!$V$44 -> 0 | BG31: =Template!$V$45 -> 0 | BH31: =Template!$V$46 -> 0 | BI31: =Template!$V$47 -> 0 | BJ31: =Template!$V$48 -> 0 | BK31: =Template!$V$52 -> 0 | BL31: =Template!$V$53 -> 0 | BM31: =Template!$V$54 -> 0 | BN31: =Template!#REF! -> #REF! | BO31: =Template!#REF! -> #REF! | BP31: =Template!#REF! -> #REF! | BQ31: =Template!#REF! -> #REF! | BR31: =Template!#REF! -> #REF! | BS31: =Template!#REF! -> #REF! | BT31: =Template!#REF! -> #REF! | BU31: =Template!#REF! -> #REF! | ... CN31: =Template!#REF! -> #REF!
A32: =Template!#REF! -> #REF! | B32: =Template!#REF! -> #REF! | C32: =Template!#REF! -> #REF! | D32: =Template!$W$1 -> 0 | E32: =Template!$W$2 -> 0 | F32: =Template!$W$3 -> 0 | G32: =Template!$W$4 -> 0 | H32: =Template!$W$5 -> 0 | I32: =Template!$W$6 -> 0 | J32: =Template!$W$7 -> 0 | K32: =Template!$W$8 -> 0 | L32: =Template!$W$9 -> 0 | M32: =Template!$W$10 -> 0 | N32: =Template!$W$11 -> 0 | O32: =Template!$W$12 -> 0 | P32: =Template!$W$13 -> 0 | Q32: =Template!$W$17 -> 0 | R32: =Template!$W$18 -> 0 | S32: =Template!$W$19 -> 0 | T32: =Template!$W$20 -> 0 | U32: =Template!$W$21 -> 0 | V32: =Template!$W$22 -> 0 | W32: =Template!#REF! -> #REF! | X32: =Template!#REF! -> #REF! | Y32: =Template!#REF! -> #REF! | Z32: =Template!#REF! -> #REF! | AA32: =Template!#REF! -> #REF! | AB32: =Template!#REF! -> #REF! | AC32: =Template!#REF! -> #REF! | AD32: =Template!#REF! -> #REF! | ... AH32: =Template!#REF! -> #REF! | AI32: =Template!$W$28 -> 0 | AJ32: =Template!$W$29 -> 0 | AK32: =Template!$W$30 -> 0 | AL32: =Template!$W$31 -> 0 | AM32: =Template!$W$32 -> 0 | AN32: =Template!$W$33 -> 0 | AO32: =Template!$W$34 -> 0 | AP32: =Template!$W$35 -> 0 | AQ32: =Template!#REF! -> #REF! | AR32: =Template!#REF! -> #REF! | AS32: =Template!#REF! -> #REF! | AT32: =Template!#REF! -> #REF! | AU32: =Template!#REF! -> #REF! | AV32: =Template!#REF! -> #REF! | AW32: =Template!#REF! -> #REF! | AX32: =Template!#REF! -> #REF! | AY32: =Template!$W$37 -> 0 | AZ32: =Template!$W$38 -> 0 | BA32: =Template!$W$39 -> 0 | BB32: =Template!$W$40 -> 0 | BC32: =Template!$W$41 -> 0 | BD32: =Template!$W$42 -> 0 | BE32: =Template!$W$43 -> 0 | BF32: =Template!$W$44 -> 0 | BG32: =Template!$W$45 -> 0 | BH32: =Template!$W$46 -> 0 | BI32: =Template!$W$47 -> 0 | BJ32: =Template!$W$48 -> 0 | BK32: =Template!$W$52 -> 0 | BL32: =Template!$W$53 -> 0 | BM32: =Template!$W$54 -> 0 | BN32: =Template!#REF! -> #REF! | BO32: =Template!#REF! -> #REF! | BP32: =Template!#REF! -> #REF! | BQ32: =Template!#REF! -> #REF! | BR32: =Template!#REF! -> #REF! | BS32: =Template!#REF! -> #REF! | BT32: =Template!#REF! -> #REF! | BU32: =Template!#REF! -> #REF! | ... CN32: =Template!#REF! -> #REF!
A33: =Template!#REF! -> #REF! | B33: =Template!#REF! -> #REF! | C33: =Template!#REF! -> #REF! | D33: =Template!$X$1 -> 0 | E33: =Template!$X$2 -> 0 | F33: =Template!$X$3 -> 0 | G33: =Template!$X$4 -> 0 | H33: =Template!$X$5 -> 0 | I33: =Template!$X$6 -> 0 | J33: =Template!$X$7 -> 0 | K33: =Template!$X$8 -> 0 | L33: =Template!$X$9 -> 0 | M33: =Template!$X$10 -> 0 | N33: =Template!$X$11 -> 0 | O33: =Template!$X$12 -> 0 | P33: =Template!$X$13 -> 0 | Q33: =Template!$X$17 -> 0 | R33: =Template!$X$18 -> 0 | S33: =Template!$X$19 -> 0 | T33: =Template!$X$20 -> 0 | U33: =Template!$X$21 -> 0 | V33: =Template!$X$22 -> 0 | W33: =Template!#REF! -> #REF! | X33: =Template!#REF! -> #REF! | Y33: =Template!#REF! -> #REF! | Z33: =Template!#REF! -> #REF! | AA33: =Template!#REF! -> #REF! | AB33: =Template!#REF! -> #REF! | AC33: =Template!#REF! -> #REF! | AD33: =Template!#REF! -> #REF! | ... AH33: =Template!#REF! -> #REF! | AI33: =Template!$X$28 -> 0 | AJ33: =Template!$X$29 -> 0 | AK33: =Template!$X$30 -> 0 | AL33: =Template!$X$31 -> 0 | AM33: =Template!$X$32 -> 0 | AN33: =Template!$X$33 -> 0 | AO33: =Template!$X$34 -> 0 | AP33: =Template!$X$35 -> 0 | AQ33: =Template!#REF! -> #REF! | AR33: =Template!#REF! -> #REF! | AS33: =Template!#REF! -> #REF! | AT33: =Template!#REF! -> #REF! | AU33: =Template!#REF! -> #REF! | AV33: =Template!#REF! -> #REF! | AW33: =Template!#REF! -> #REF! | AX33: =Template!#REF! -> #REF! | AY33: =Template!$X$37 -> 0 | AZ33: =Template!$X$38 -> 0 | BA33: =Template!$X$39 -> 0 | BB33: =Template!$X$40 -> 0 | BC33: =Template!$X$41 -> 0 | BD33: =Template!$X$42 -> 0 | BE33: =Template!$X$43 -> 0 | BF33: =Template!$X$44 -> 0 | BG33: =Template!$X$45 -> 0 | BH33: =Template!$X$46 -> 0 | BI33: =Template!$X$47 -> 0 | BJ33: =Template!$X$48 -> 0 | BK33: =Template!$X$52 -> 0 | BL33: =Template!$X$53 -> 0 | BM33: =Template!$X$54 -> 0 | BN33: =Template!#REF! -> #REF! | BO33: =Template!#REF! -> #REF! | BP33: =Template!#REF! -> #REF! | BQ33: =Template!#REF! -> #REF! | BR33: =Template!#REF! -> #REF! | BS33: =Template!#REF! -> #REF! | BT33: =Template!#REF! -> #REF! | BU33: =Template!#REF! -> #REF! | ... CN33: =Template!#REF! -> #REF!
